Workbook

Sheet 角色
A1: 编号 | B1: 基础信息 | K1: 升级材料 | R1: 天赋材料 | Y1: 圣遗物 属性权重 | AG1: 圣遗物套装推荐 | AJ1: 基础属性 | AO1: 进阶属性 | AV1: 元素属性
B2: 地区 | D2: 角色名 | F2: 命之座 | G2: 生日 | H2: 星级 | I2: 属性 | J2: 武器 | K2: 突破材料 | O2: 天赋材料 | R2: 天赋副本开启日期 | Y2: HP | Z2: ATK | AA2: DEF | AB2: CRIT Rate | AC2: CRIT DMG | AD2: EM | AE2: ER | AJ2: 生命值 | AK2: 攻击力 | AL2: 防御力 | AM2: 元素精通 | AN2: 体力上限 | AO2: 暴击 | AQ2: 治疗 | AS2: 元素充能效率 | AT2: 冷却缩减 | AU2: 护盾强效 | AV2: 火 | AX2: 水 | AZ2: 草 | BB2: 雷 | BD2: 风 | BF2: 冰 | BH2: 岩 | BJ2: 物理
B3: 国家 | C3: 所属 | D3: 中文 | E3: 英文 | K3: 石头 | L3: 世界boss | M3: 地图探索 | N3: 世界怪物 | O3: 讨伐 | P3: 世界怪物 | Q3: 秘境 | R3: 周一 | S3: 周二 | T3: 周三 | U3: 周四 | V3: 周五 | W3: 周六 | X3: 周日 | Y3: 生命值 | Z3: 攻击力 | AA3: 防御力 | AB3: 暴击率 | AC3: 暴击伤害 | AD3: 元素精通 | AE3: 元素充能 | AF3: 治疗 | AO3: 率 | AP3: 伤害 | AQ3: 治疗加成 | AR3: 受治疗加成 | AV3: 伤害 | AW3: 抗性 | AX3: 伤害 | AY3: 抗性 | AZ3: 伤害 | BA3: 抗性 | BB3: 伤害 | BC3: 抗性 | BD3: 伤害 | BE3: 抗性 | BF3: 伤害 | BG3: 抗性 | BH3: 伤害 | BI3: 抗性 | BJ3: 伤害 | BK3: 抗性
A4: -7 | B4: - | C4: - | D4: 旅行者-风 | E4: 风元素 Anemo | H4: 5 | I4: 风 | J4: 单手剑 | K4: 璀璨原钻 | L4: - | M4: 风车菊 | N4: 丘丘人 | O4: 深入风龙废墟 | P4: 丘丘萨满 | Q4: 自由 抗争 诗文 | R4: 1 | S4: 1 | T4: 1 | U4: 1 | V4: 1 | W4: 1 | X4: 1 | Y4: 0 | Z4: 75 | AA4: 0 | AB4: 100 | AC4: 100 | AD4: 75 | AE4: 0
A5: -6 | B5: - | C5: - | D5: 旅行者-岩 | E5: 岩元素 Geo | H5: 5 | I5: 岩 | J5: 单手剑 | K5: 璀璨原钻 | L5: - | M5: 风车菊 | N5: 丘丘人 | O5: 深入风龙废墟 | P5: 丘丘萨满 | Q5: 自由 抗争 诗文 | R5: 1 | S5: 1 | T5: 1 | U5: 1 | V5: 1 | W5: 1 | X5: 1 | Y5: 0 | Z5: 75 | AA5: 0 | AB5: 100 | AC5: 100 | AD5: 0 | AE5: 0
A6: -5 | B6: - | C6: - | D6: 旅行者-雷 | E6: 雷元素 Electro | H6: 5 | I6: 雷 | J6: 单手剑 | K6: 璀璨原钻 | L6: - | M6: 风车菊 | N6: 丘丘人 | O6: 伏龙树 之底 | P6: 野伏众 | Q6: 浮世 风雅 天光 | R6: 1 | S6: 1 | T6: 1 | U6: 1 | V6: 1 | W6: 1 | X6: 1 | Y6: 0 | Z6: 75 | AA6: 0 | AB6: 100 | AC6: 100 | AD6: 75 | AE6: 0
A7: -4 | B7: - | C7: - | D7: 旅行者-草 | E7: 草元素 Dendro | H7: 5 | I7: 草 | J7: 单手剑 | K7: 璀璨原钻 | L7: - | M7: 风车菊 | N7: 丘丘人 | O7: 梦想乐土之役 | P7: 蕈兽 | Q7: 净言 巧思 笃行 | R7: 1 | S7: 1 | T7: 1 | U7: 1 | V7: 1 | W7: 1 | X7: 1 | Y7: 0 | Z7: 75 | AA7: 0 | AB7: 100 | AC7: 100 | AD7: 75 | AE7: 55
A8: -3 | B8: - | C8: - | D8: 旅行者-水 | E8: 水元素 Hydro | H8: 5 | I8: 水 | J8: 单手剑 | K8: 璀璨原钻 | L8: - | M8: 风车菊 | N8: 丘丘人 | O8: 肇始之乡 | P8: 原海异种 | Q8: 公平 正义 秩序 | R8: 1 | S8: 1 | T8: 1 | U8: 1 | V8: 1 | W8: 1 | X8: 1 | Y8: 11 | Z8: 22 | AA8: 33 | AB8: 44 | AC8: 55 | AD8: 66 | AE8: 77
A9: -2 | B9: - | C9: - | D9: 旅行者-火 | E9: 火元素 Pyro | H9: 5 | I9: 火 | J9: 单手剑 | K9: 璀璨原钻 | L9: - | M9: 风车菊 | N9: 丘丘人 | R9: 1 | S9: 1 | T9: 1 | U9: 1 | V9: 1 | W9: 1 | X9: 1
A10: -1 | B10: - | C10: - | D10: 旅行者-冰 | E10: 冰元素 Cryo | H10: 5 | I10: 冰 | J10: 单手剑 | K10: 璀璨原钻 | L10: - | M10: 风车菊 | N10: 丘丘人 | R10: 1 | S10: 1 | T10: 1 | U10: 1 | V10: 1 | W10: 1 | X10: 1
A11: 0 | B11: - | C11: - | D11: 空 | E11: Aether | H11: 5 | I11: 无 | J11: 单手剑 | K11: 璀璨原钻 | L11: - | M11: 风车菊 | N11: 丘丘人 | R11: 1 | S11: 1 | T11: 1 | U11: 1 | V11: 1 | W11: 1 | X11: 1 | Y11: 生命值 | Z11: 攻击力 | AA11: 防御力 | AB11: 暴击率 | AC11: 暴击伤害 | AD11: 元素精通 | AE11: 元素充能 | AF11: 治疗
A12: 0 | B12: - | C12: - | D12: 荧 | E12: Lumine | H12: 5 | I12: 无 | J12: 单手剑 | K12: 璀璨原钻 | L12: - | M12: 风车菊 | N12: 丘丘人 | R12: 1 | S12: 1 | T12: 1 | U12: 1 | V12: 1 | W12: 1 | X12: 1
A13: 1 | B13: 蒙德 | C13: 西风骑士团 | D13: 可莉 | E13: Klee | F13: 四叶草座 | G13: 45500 | H13: 5 | I13: 火 | J13: 法器 | K13: 燃愿玛瑙 | L13: 爆炎树 | M13: 慕风蘑菇 | N13: 丘丘萨满 | O13: 北风的王狼 | P13: 丘丘萨满 | Q13: 自由 | R13: 1 | U13: 1 | X13: 1 | Y13: 0 | Z13: 75 | AA13: 0 | AB13: 100 | AC13: 100 | AD13: 75 | AE13: 0 | AJ13: 10287 | AK13: 311 | AL13: 615 | AV13: 0.288
A14: 2 | B14: 蒙德 | C14: 蒙德城 | D14: 温迪 | E14: Venti | F14: 歌仙座 | G14: 45459 | H14: 5 | I14: 风 | J14: 弓 | K14: 自在松石 | L14: 无相之风 | M14: 塞西莉亚花 | N14: 史莱姆 | O14: 北风的王狼 | P14: 史莱姆 | Q14: 诗文 | T14: 1 | W14: 1 | X14: 1 | Y14: 0 | Z14: 75 | AA14: 0 | AB14: 100 | AC14: 100 | AD14: 75 | AE14: 55 | AJ14: 10531 | AK14: 263 | AL14: 669 | AS14: 0.32
A15: 3 | B15: 璃月 | C15: 璃月七星 | D15: 刻晴 | E15: Keqing | F15: 金紫 | H15: 5 | I15: 雷 | J15: 单手剑 | K15: 最胜紫晶 | L15: 无相之雷 | M15: 石珀 | N15: 骗骗花 | O15: 北风的王狼 | P15: 骗骗花 | Q15: 繁荣 | R15: 1 | U15: 1 | X15: 1 | Y15: 0 | Z15: 75 | AA15: 0 | AB15: 100 | AC15: 100 | AD15: 75 | AE15: 0
A16: 4 | B16: 蒙德 | C16: 蒙德城 | D16: 莫娜 | E16: Mona | H16: 5 | I16: 水 | J16: 法器 | K16: 涤净青金 | L16: 纯水精灵 | M16: 慕风蘑菇 | N16: 骗骗花 | O16: 北风的王狼 | P16: 骗骗花 | Q16: 抗争 | S16: 1 | V16: 1 | X16: 1 | Y16: 0 | Z16: 75 | AA16: 0 | AB16: 100 | AC16: 100 | AD16: 75 | AE16: 75
A17: 5 | B17: 璃月 | D17: 七七 | E17: Qiqi | H17: 5 | I17: 冰 | J17: 单手剑 | K17: 哀叙冰玉 | L17: 急冻树 | M17: 琉璃袋 | N17: 丘丘萨满 | O17: 北风的王狼 | P17: 丘丘萨满 | Q17: 繁荣 | R17: 1 | U17: 1 | X17: 1 | Y17: 0 | Z17: 100 | AA17: 0 | AB17: 100 | AC17: 100 | AD17: 0 | AE17: 55
A18: 6 | B18: 蒙德 | D18: 迪卢克 | E18: Diluc | H18: 5 | I18: 火 | J18: 双手剑 | K18: 燃愿玛瑙 | L18: 爆炎树 | M18: 小灯草 | N18: 愚人众 | O18: 深入风龙废墟 | P18: 愚人众 | Q18: 抗争 | S18: 1 | V18: 1 | X18: 1 | Y18: 0 | Z18: 75 | AA18: 0 | AB18: 100 | AC18: 100 | AD18: 75 | AE18: 0
A19: 7 | B19: 蒙德 | D19: 琴 | E19: Jean | H19: 5 | I19: 风 | J19: 单手剑 | K19: 自在松石 | L19: 无相之风 | M19: 蒲公英籽 | N19: 丘丘人 | O19: 深入风龙废墟 | P19: 丘丘人 | Q19: 抗争 | S19: 1 | V19: 1 | X19: 1 | Y19: 0 | Z19: 75 | AA19: 0 | AB19: 100 | AC19: 100 | AD19: 75 | AE19: 55
A20: 8 | B20: 蒙德 | D20: 砂糖 | E20: Sucrose | H20: 4 | I20: 风 | J20: 法器 | K20: 自在松石 | L20: 无相之风 | M20: 风车菊 | N20: 骗骗花 | O20: 北风的王狼 | P20: 骗骗花 | Q20: 自由 | R20: 1 | U20: 1 | X20: 1 | Y20: 0 | Z20: 75 | AA20: 0 | AB20: 100 | AC20: 100 | AD20: 100 | AE20: 55
A21: 9 | B21: 璃月 | D21: 重云 | E21: Chongyun | H21: 4 | I21: 冰 | J21: 双手剑 | K21: 哀叙冰玉 | L21: 急冻树 | M21: 石珀 | N21: 丘丘人 | O21: 深入风龙废墟 | P21: 丘丘人 | Q21: 勤劳 | S21: 1 | V21: 1 | X21: 1 | Y21: 0 | Z21: 75 | AA21: 0 | AB21: 100 | AC21: 100 | AD21: 75 | AE21: 55
A22: 10 | B22: 蒙德 | D22: 诺艾尔 | E22: Noelle | H22: 4 | I22: 岩 | J22: 双手剑 | K22: 坚牢黄玉 | L22: 无相之岩 | M22: 落落莓 | N22: 丘丘人 | O22: 深入风龙废墟 | P22: 丘丘人 | Q22: 抗争 | S22: 1 | V22: 1 | X22: 1 | Y22: 0 | Z22: 50 | AA22: 90 | AB22: 100 | AC22: 100 | AD22: 0 | AE22: 70 | AG22: 逐影猎人
A23: 11 | B23: 蒙德 | D23: 班尼特 | E23: Bennett | H23: 4 | I23: 火 | J23: 单手剑 | K23: 燃愿玛瑙 | L23: 爆炎树 | M23: 风车菊 | N23: 盗宝团 | O23: 深入风龙废墟 | P23: 盗宝团 | Q23: 抗争 | S23: 1 | V23: 1 | X23: 1 | Y23: 100 | Z23: 50 | AA23: 0 | AB23: 50 | AC23: 50 | AD23: 0 | AE23: 55
A24: 12 | B24: 蒙德 | D24: 菲谢尔 | E24: Fischl | H24: 4 | I24: 雷 | J24: 弓 | K24: 最胜紫晶 | L24: 无相之雷 | M24: 小灯草 | N24: 丘丘弓箭手 | O24: 北风的王狼 | P24: 丘丘弓箭手 | Q24: 诗文 | T24: 1 | W24: 1 | X24: 1 | Y24: 0 | Z24: 75 | AA24: 0 | AB24: 100 | AC24: 100 | AD24: 75 | AE24: 0
A25: 13 | B25: 璃月 | D25: 凝光 | E25: Ningguang | H25: 4 | I25: 岩 | J25: 法器 | K25: 坚牢黄玉 | L25: 无相之岩 | M25: 琉璃百合 | N25: 愚人众 | O25: 北风的王狼 | P25: 愚人众 | Q25: 繁荣 | R25: 1 | U25: 1 | X25: 1 | Y25: 0 | Z25: 75 | AA25: 0 | AB25: 100 | AC25: 100 | AD25: 0 | AE25: 0 | AG25: 回声之林夜话
A26: 14 | B26: 璃月 | D26: 行秋 | E26: Xingqiu | H26: 4 | I26: 水 | J26: 单手剑 | K26: 涤净青金 | L26: 纯水精灵 | M26: 霓裳花 | N26: 丘丘人 | O26: 北风的王狼 | P26: 丘丘人 | Q26: 黄金 | T26: 1 | W26: 1 | X26: 1 | Y26: 0 | Z26: 75 | AA26: 0 | AB26: 100 | AC26: 100 | AD26: 0 | AE26: 55
A27: 15 | B27: 璃月 | D27: 北斗 | E27: Beidou | H27: 4 | I27: 雷 | J27: 双手剑 | K27: 最胜紫晶 | L27: 无相之雷 | M27: 夜泊石 | N27: 盗宝团 | O27: 深入风龙废墟 | P27: 盗宝团 | Q27: 黄金 | T27: 1 | W27: 1 | X27: 1 | Y27: 0 | Z27: 75 | AA27: 0 | AB27: 100 | AC27: 100 | AD27: 75 | AE27: 55
A28: 16 | B28: 璃月 | D28: 香菱 | E28: Xiangling | H28: 4 | I28: 火 | J28: 长柄武器 | K28: 燃愿玛瑙 | L28: 爆炎树 | M28: 绝云椒椒 | N28: 史莱姆 | O28: 深入风龙废墟 | P28: 史莱姆 | Q28: 勤劳 | S28: 1 | V28: 1 | X28: 1 | Y28: 0 | Z28: 75 | AA28: 0 | AB28: 100 | AC28: 100 | AD28: 75 | AE28: 55
A29: 17 | B29: 蒙德 | D29: 雷泽 | E29: Razor | H29: 4 | I29: 雷 | J29: 双手剑 | K29: 最胜紫晶 | L29: 无相之雷 | M29: 勾勾果 | N29: 丘丘人 | O29: 深入风龙废墟 | P29: 丘丘人 | Q29: 抗争 | S29: 1 | V29: 1 | X29: 1 | Y29: 0 | Z29: 75 | AA29: 0 | AB29: 100 | AC29: 100 | AD29: 0 | AE29: 0
A30: 18 | B30: 蒙德 | D30: 芭芭拉 | E30: Barbara | H30: 4 | I30: 水 | J30: 法器 | K30: 涤净青金 | L30: 纯水精灵 | M30: 慕风蘑菇 | N30: 丘丘萨满 | O30: 北风的王狼 | P30: 丘丘萨满 | Q30: 自由 | R30: 1 | U30: 1 | X30: 1 | Y30: 100 | Z30: 50 | AA30: 0 | AB30: 50 | AC30: 50 | AD30: 0 | AE30: 55
A31: 19 | B31: 蒙德 | D31: 丽莎 | E31: Lisa | H31: 4 | I31: 雷 | J31: 法器 | K31: 最胜紫晶 | L31: 无相之雷 | M31: 落落莓 | N31: 史莱姆 | O31: 深入风龙废墟 | P31: 史莱姆 | Q31: 诗文 | T31: 1 | W31: 1 | X31: 1 | Y31: 0 | Z31: 75 | AA31: 0 | AB31: 100 | AC31: 100 | AD31: 75 | AE31: 0
A32: 20 | B32: 蒙德 | D32: 凯亚 | E32: Kaeya | H32: 4 | I32: 冰 | J32: 单手剑 | K32: 哀叙冰玉 | L32: 急冻树 | M32: 嘟嘟莲 | N32: 盗宝团 | O32: 北风的王狼 | P32: 盗宝团 | Q32: 诗文 | T32: 1 | W32: 1 | X32: 1 | Y32: 0 | Z32: 75 | AA32: 0 | AB32: 100 | AC32: 100 | AD32: 0 | AE32: 0
A33: 21 | B33: 蒙德 | D33: 安柏 | E33: Amber | H33: 4 | I33: 火 | J33: 弓 | K33: 燃愿玛瑙 | L33: 爆炎树 | M33: 小灯草 | N33: 丘丘弓箭手 | O33: 深入风龙废墟 | P33: 丘丘弓箭手 | Q33: 自由 | R33: 1 | U33: 1 | X33: 1 | Y33: 0 | Z33: 75 | AA33: 0 | AB33: 100 | AC33: 100 | AD33: 75 | AE33: 0
A34: 22 | B34: 至冬 | D34: 达达利亚 | E34: Tartaglia | H34: 5 | I34: 水 | J34: 弓 | K34: 涤净青金 | L34: 纯水精灵 | M34: 星螺 | N34: 愚人众 | O34: 进入 黄金屋 | P34: 愚人众 | Q34: 自由 | R34: 1 | U34: 1 | X34: 1 | Y34: 0 | Z34: 75 | AA34: 0 | AB34: 100 | AC34: 100 | AD34: 75 | AE34: 0
A35: 23 | B35: 蒙德 | D35: 迪奥娜 | E35: Diona | H35: 4 | I35: 冰 | J35: 弓 | K35: 哀叙冰玉 | L35: 急冻树 | M35: 嘟嘟莲 | N35: 丘丘弓箭手 | O35: 进入 黄金屋 | P35: 丘丘弓箭手 | Q35: 自由 | R35: 1 | U35: 1 | X35: 1 | Y35: 100 | Z35: 50 | AA35: 0 | AB35: 50 | AC35: 50 | AD35: 0 | AE35: 90
A36: 24 | B36: 璃月 | D36: 钟离 | E36: Zhongli | H36: 5 | I36: 岩 | J36: 长柄武器 | K36: 坚牢黄玉 | L36: 无相之岩 | M36: 石珀 | N36: 史莱姆 | O36: 进入 黄金屋 | P36: 史莱姆 | Q36: 黄金 | T36: 1 | W36: 1 | X36: 1 | Y36: 80 | Z36: 75 | AA36: 0 | AB36: 100 | AC36: 100 | AD36: 0 | AE36: 55
A37: 25 | B37: 璃月 | D37: 辛焱 | E37: Xinyan | H37: 4 | I37: 火 | J37: 双手剑 | K37: 燃愿玛瑙 | L37: 爆炎树 | M37: 琉璃袋 | N37: 盗宝团 | O37: 进入 黄金屋 | P37: 盗宝团 | Q37: 黄金 | T37: 1 | W37: 1 | X37: 1 | Y37: 0 | Z37: 75 | AA37: 0 | AB37: 100 | AC37: 100 | AD37: 0 | AE37: 55
A38: 26 | B38: 蒙德 | D38: 阿贝多 | E38: Albedo | H38: 5 | I38: 岩 | J38: 单手剑 | K38: 坚牢黄玉 | L38: 无相之岩 | M38: 塞西莉亚花 | N38: 丘丘萨满 | O38: 进入 黄金屋 | P38: 丘丘萨满 | Q38: 诗文 | T38: 1 | W38: 1 | X38: 1 | Y38: 0 | Z38: 0 | AA38: 100 | AB38: 100 | AC38: 100 | AD38: 0 | AE38: 0 | AG38: 黄金剧团
A39: 27 | B39: 璃月 | D39: 甘雨 | E39: Ganyu | H39: 5 | I39: 冰 | J39: 弓 | K39: 哀叙冰玉 | L39: 急冻树 | M39: 清心 | N39: 骗骗花 | O39: 进入 黄金屋 | P39: 骗骗花 | Q39: 勤劳 | S39: 1 | V39: 1 | X39: 1 | Y39: 0 | Z39: 75 | AA39: 0 | AB39: 100 | AC39: 100 | AD39: 75 | AE39: 0
A40: 28 | B40: 璃月 | D40: 魈 | E40: Xiao | H40: 5 | I40: 风 | J40: 长柄武器 | K40: 自在松石 | L40: 古岩龙蜥 | M40: 清心 | N40: 史莱姆 | O40: 进入 黄金屋 | P40: 史莱姆 | Q40: 繁荣 | R40: 1 | U40: 1 | X40: 1 | Y40: 0 | Z40: 75 | AA40: 0 | AB40: 100 | AC40: 100 | AD40: 0 | AE40: 55 | AG40: 逐影猎人
...

Sheet 武器汇总
A1: 编号 | B1: 名称 | C1: 星级 | D1: 武器类型 | E1: 突破材料 | J1: 武器副本开启日期
E2: 世界怪物 | F2: 怪物家族 | I2: 秘境 | J2: 周一 | K2: 周二 | L2: 周三 | M2: 周四 | N2: 周五 | O2: 周六 | P2: 周日
A3: 1 | B3: 阿莫斯之弓 | C3: 5 | D3: 弓 | F3: 幼岩龙斯 | G3: 岩龙断 | H3: 深海龙蜥
A4: 2 | B4: 碧落之珑 | C4: 5 | D4: 法器
A5: 3 | B5: 波乱月白经津 | C5: 5 | D5: 单手剑
A6: 4 | B6: 不灭月华 | C6: 5 | D6: 法器
A7: 5 | B7: 裁断 | C7: 5 | D7: 双手剑
A8: 6 | B8: 裁叶萃光 | C8: 5 | D8: 单手剑
A9: 7 | B9: 苍古自由之誓 | C9: 5 | D9: 单手剑
A10: 8 | B10: 尘世之锁 | C10: 5 | D10: 法器 | F10: 幼岩龙斯 | G10: 岩龙断 | H10: 深海龙蜥
A11: 9 | B11: 赤角石溃杵 | C11: 5 | D11: 双手剑
A12: 10 | B12: 赤沙之杖 | C12: 5 | D12: 长柄武器
A13: 11 | B13: 冬极白星 | C13: 5 | D13: 弓
A14: 12 | B14: 飞雷之弦振 | C14: 5 | D14: 弓
A15: 13 | B15: 风鹰剑 | C15: 5 | D15: 单手剑
A16: 14 | B16: 贯虹之塑 | C16: 5 | D16: 长柄武器 | F16: 幼岩龙斯 | G16: 岩龙断 | H16: 深海龙蜥
A17: 15 | B17: 鹤鸣余音 | C17: 5 | D17: 法器
A18: 16 | B18: 和璞鸢 | C18: 5 | D18: 长柄武器
A19: 17 | B19: 护摩之杖 | C19: 5 | D19: 长柄武器
A20: 18 | B20: 静水流涌之辉 | C20: 5 | D20: 单手剑
A21: 19 | B21: 金流监督 | C21: 5 | D21: 法器
A22: 20 | B22: 狼的末路 | C22: 5 | D22: 双手剑
A23: 21 | B23: 猎人之径 | C23: 5 | D23: 弓
A24: 22 | B24: 磐岩结绿 | C24: 5 | D24: 单手剑
A25: 23 | B25: 千夜浮梦 | C25: 5 | D25: 法器
A26: 24 | B26: 若水 | C26: 5 | D26: 弓
A27: 25 | B27: 圣显之钥 | C27: 5 | D27: 单手剑
A28: 26 | B28: 神乐之真意 | C28: 5 | D28: 法器
... A117: 115 | B117: 万国诸海图谱 | C117: 4 | D117: 法器
A118: 116 | B118: 无垠蔚蓝之歌 | C118: 4 | D118: 法器 | F118: 幼岩龙斯 | G118: 岩龙断 | H118: 深海龙蜥
A119: 117 | B119: 衔珠海皇 | C119: 4 | D119: 双手剑
A120: 118 | B120: 匣里龙吟 | C120: 4 | D120: 单手剑
A121: 119 | B121: 匣里灭辰 | C121: 4 | D121: 长柄武器
A122: 120 | B122: 匣里日月 | C122: 4 | D122: 法器
A123: 121 | B123: 峡湾长歌 | C123: 4 | D123: 长柄武器
A124: 122 | B124: 喜多院十文字 | C124: 4 | D124: 长柄武器
A125: 123 | B125: 西风长枪 | C125: 4 | D125: 长柄武器
A126: 124 | B126: 西风大剑 | C126: 4 | D126: 双手剑
A127: 125 | B127: 西风剑 | C127: 4 | D127: 单手剑
A128: 126 | B128: 西风猎弓 | C128: 4 | D128: 弓
...

Sheet 圣遗物得分计算
A1: 编号 | B1: 名称 | C1: 部位 | D1: 等级 | E1: 主词条 | W1: 副词条 | AG1: 合计 | AS1: 得分
E2: 通配 | I2: 生之花 | J2: 死之羽 | K2: 时之沙 | L2: 空之杯-元素伤害加成 | T2: 理之冠 | W2: 攻击力 | Y2: 生命力 | AA2: 防御力 | AC2: 暴击率 | AG2: 生命值 | AH2: 攻击力 | AI2: 防御力 | AJ2: 生命值百分比 | AK2: 攻击力百分比 | AL2: 防御力百分比 | AM2: 暴击率 | AN2: 暴击伤害 | AO2: 元素精通 | AP2: 元素充能 | AQ2: 元素伤害 | AR2: 治疗加成
A3: 角色 | B3: 芙宁娜 | E3: 生命值% | F3: 攻击力% | G3: 防御力% | H3: 元素精通 | I3: 生命值 | J3: 攻击力 | K3: 元素充能 | L3: 物理 | M3: 风 | N3: 火 | O3: 雷 | P3: 水 | Q3: 草 | R3: 冰 | S3: 岩 | T3: 治疗加成 | U3: 暴击率 | V3: 暴击伤害 | W3: 数值 | X3: 百分比 | Y3: 数值 | Z3: 百分比 | AA3: 数值 | AB3: 百分比 | AC3: 暴击率 | AD3: 暴击伤害 | AE3: 元素精通 | AF3: 元素充能 | AG3: HP^0.026*0 66 | AH3: ATK*0.398*0 5 | AI3: DEF^0 .335*0 66 | AJ3: HP%*1.33 | AK3: ATK%*1.33 | AL3: DEF%*1.06 | AM3: CRiT Rate*2 | AN3: CRIT DMG*1 | AO3: EM*1 | AP3: ER*1.1979
A4: 权重占比 | E4: =_xlfn.XLOOKUP($B$3,角色!$D:$D,角色!Y:Y) -> 100 | F4: =_xlfn.XLOOKUP($B$3,角色!$D:$D,角色!Z:Z) -> 75 | G4: =_xlfn.XLOOKUP($B$3,角色!$D:$D,角色!AA:AA) -> 0 | H4: =_xlfn.XLOOKUP($B$3,角色!$D:$D,角色!AD:AD) -> 0 | I4: =_xlfn.XLOOKUP($B$3,角色!$D:$D,角色!Y:Y) -> 100 | J4: =_xlfn.XLOOKUP($B$3,角色!$D:$D,角色!Z:Z) -> 75 | K4: =_xlfn.XLOOKUP($B$3,角色!$D:$D,角色!AE:AE) -> 75 | L4: =IF(_xlfn.XLOOKUP($B$3,角色!$D:$D,角色!$I:$I)=L3,1,0) -> 0 | M4: =IF(_xlfn.XLOOKUP($B$3,角色!$D:$D,角色!$I:$I)=M3,1,0) -> 0 | N4: =IF(_xlfn.XLOOKUP($B$3,角色!$D:$D,角色!$I:$I)=N3,1,0) -> 0 | O4: =IF(_xlfn.XLOOKUP($B$3,角色!$D:$D,角色!$I:$I)=O3,1,0) -> 0 | P4: =IF(_xlfn.XLOOKUP($B$3,角色!$D:$D,角色!$I:$I)=P3,1,0) -> 1 | Q4: =IF(_xlfn.XLOOKUP($B$3,角色!$D:$D,角色!$I:$I)=Q3,1,0) -> 0 | R4: =IF(_xlfn.XLOOKUP($B$3,角色!$D:$D,角色!$I:$I)=R3,1,0) -> 0 | S4: =IF(_xlfn.XLOOKUP($B$3,角色!$D:$D,角色!$I:$I)=S3,1,0) -> 0 | T4: =_xlfn.XLOOKUP($B$3,角色!$D:$D,角色!AF:AF) -> 100 | U4: =_xlfn.XLOOKUP($B$3,角色!$D:$D,角色!AB:AB) -> 100 | V4: =_xlfn.XLOOKUP($B$3,角色!$D:$D,角色!AC:AC) -> 100 | W4: =_xlfn.XLOOKUP($B$3,角色!$D:$D,角色!Z:Z) -> 75 | X4: =_xlfn.XLOOKUP($B$3,角色!$D:$D,角色!Z:Z) -> 75 | Y4: =_xlfn.XLOOKUP($B$3,角色!$D:$D,角色!Y:Y) -> 100 | Z4: =_xlfn.XLOOKUP($B$3,角色!$D:$D,角色!Y:Y) -> 100 | AA4: =_xlfn.XLOOKUP($B$3,角色!$D:$D,角色!AA:AA) -> 0 | AB4: =_xlfn.XLOOKUP($B$3,角色!$D:$D,角色!AA:AA) -> 0 | AC4: =_xlfn.XLOOKUP($B$3,角色!$D:$D,角色!AB:AB) -> 100 | AD4: =_xlfn.XLOOKUP($B$3,角色!$D:$D,角色!AC:AC) -> 100 | AE4: =_xlfn.XLOOKUP($B$3,角色!$D:$D,角色!AD:AD) -> 0 | AF4: =_xlfn.XLOOKUP($B$3,角色!$D:$D,角色!AE:AE) -> 75 | AG4: =_xlfn.XLOOKUP($B$3,角色!$D:$D,角色!Y:Y) -> 100 | AH4: =_xlfn.XLOOKUP($B$3,角色!$D:$D,角色!Z:Z) -> 75 | AI4: =_xlfn.XLOOKUP($B$3,角色!$D:$D,角色!AA:AA) -> 0 | AJ4: =_xlfn.XLOOKUP($B$3,角色!$D:$D,角色!Y:Y) -> 100 | AK4: =_xlfn.XLOOKUP($B$3,角色!$D:$D,角色!Z:Z) -> 75 | AL4: =_xlfn.XLOOKUP($B$3,角色!$D:$D,角色!AA:AA) -> 0 | AM4: =_xlfn.XLOOKUP($B$3,角色!$D:$D,角色!AB:AB) -> 100 | AN4: =_xlfn.XLOOKUP($B$3,角色!$D:$D,角色!AC:AC) -> 100 | AO4: =_xlfn.XLOOKUP($B$3,角色!$D:$D,角色!AD:AD) -> 0 | AP4: =_xlfn.XLOOKUP($B$3,角色!$D:$D,角色!AE:AE) -> 75 | AQ4: 100 | AR4: =_xlfn.XLOOKUP($B$3,角色!$D:$D,角色!AF:AF) -> 100
A5: 1 | B5: 黄金剧团 | C5: 花 | D5: 20 | I5: 4780 | W5: 35 | Z5: 0.041 | AC5: 0.132 | AD5: 0.132 | AG5: =(I5+Y5)^0.026*0.66 -> 0.82263856 | AH5: =(J5+W5)*0.398*0.5 -> 6.965 | AI5: =(AA5)^0.335*0.66 -> 0 | AJ5: =(E5+Z5)*1.33 -> 0.05453 | AK5: =(F5+X5)*1.33 -> 0 | AL5: =(G5+AB5)*1.06 -> 0 | AM5: =(U5+AC5)*2 -> 0.264 | AN5: =(V5+AD5)*1 -> 0.132 | AO5: =(H5+AE5)*1 -> 0 | AP5: =(K5+AF5)*1.1979 -> 0 | AQ5: =L5+M5+N5+O5+P5+Q5+R5+S5 -> 0 | AR5: =T5 -> 0 | AS5: =AG5*$AG$4+AH5*$AH$4+AI5*$AI$4+AJ5*$AJ$4+AK5*$AK$4+AL5*$AL$4+AM5*$AM$4+AN5*$AN$4+AO5*$AO$4+AP5*$AP$4+AQ5*$AQ$4+AR5*$AR$4 -> 649.69186
A6: 2 | B6: 黄金剧团 | C6: 羽 | D6: 20 | J6: 311 | X6: 0.041 | AB6: 0.131 | AD6: 0.187 | AF6: 0.104 | AG6: =(I6+Y6)^0.026*0.66 -> 0 | AH6: =(J6+W6)*0.398*0.5 -> 61.889 | AI6: =(AA6)^0.335*0.66 -> 0 | AJ6: =(E6+Z6)*1.33 -> 0 | AK6: =(F6+X6)*1.33 -> 0.05453 | AL6: =(G6+AB6)*1.06 -> 0.13886 | AM6: =(U6+AC6)*2 -> 0 | AN6: =(V6+AD6)*1 -> 0.187 | AO6: =(H6+AE6)*1 -> 0 | AP6: =(K6+AF6)*1.1979 -> 0.1245816 | AQ6: =L6+M6+N6+O6+P6+Q6+R6+S6 -> 0 | AR6: =T6 -> 0 | AS6: =AG6*$AG$4+AH6*$AH$4+AI6*$AI$4+AJ6*$AJ$4+AK6*$AK$4+AL6*$AL$4+AM6*$AM$4+AN6*$AN$4+AO6*$AO$4+AP6*$AP$4+AQ6*$AQ$4+AR6*$AR$4 -> 4673.8084
A7: 3 | B7: 黄金剧团 | C7: 沙 | D7: 20 | F7: 0.466 | W7: 29 | Z7: 0.099 | AD7: 0.117 | AF7: 0.142 | AG7: =(I7+Y7)^0.026*0.66 -> 0 | AH7: =(J7+W7)*0.398*0.5 -> 5.771 | AI7: =(AA7)^0.335*0.66 -> 0 | AJ7: =(E7+Z7)*1.33 -> 0.13167 | AK7: =(F7+X7)*1.33 -> 0.61978 | AL7: =(G7+AB7)*1.06 -> 0 | AM7: =(U7+AC7)*2 -> 0 | AN7: =(V7+AD7)*1 -> 0.117 | AO7: =(H7+AE7)*1 -> 0 | AP7: =(K7+AF7)*1.1979 -> 0.1701018 | AQ7: =L7+M7+N7+O7+P7+Q7+R7+S7 -> 0 | AR7: =T7 -> 0 | AS7: =AG7*$AG$4+AH7*$AH$4+AI7*$AI$4+AJ7*$AJ$4+AK7*$AK$4+AL7*$AL$4+AM7*$AM$4+AN7*$AN$4+AO7*$AO$4+AP7*$AP$4+AQ7*$AQ$4+AR7*$AR$4 -> 516.93313
A8: 4 | B8: 黄金剧团 | C8: 沙 | D8: 20 | E8: 0.466 | W8: 39 | AC8: 0.058 | AE8: 61 | AF8: 0.045 | AG8: =(I8+Y8)^0.026*0.66 -> 0 | AH8: =(J8+W8)*0.398*0.5 -> 7.761 | AI8: =(AA8)^0.335*0.66 -> 0 | AJ8: =(E8+Z8)*1.33 -> 0.61978 | AK8: =(F8+X8)*1.33 -> 0 | AL8: =(G8+AB8)*1.06 -> 0 | AM8: =(U8+AC8)*2 -> 0.116 | AN8: =(V8+AD8)*1 -> 0 | AO8: =(H8+AE8)*1 -> 61 | AP8: =(K8+AF8)*1.1979 -> 0.0539055 | AQ8: =L8+M8+N8+O8+P8+Q8+R8+S8 -> 0 | AR8: =T8 -> 0 | AS8: =AG8*$AG$4+AH8*$AH$4+AI8*$AI$4+AJ8*$AJ$4+AK8*$AK$4+AL8*$AL$4+AM8*$AM$4+AN8*$AN$4+AO8*$AO$4+AP8*$AP$4+AQ8*$AQ$4+AR8*$AR$4 -> 659.69591
A9: 5 | B9: 黄金剧团 | C9: 杯 | D9: 20 | E9: 0.466 | X9: 0.087 | Y9: 508 | AE9: 61 | AF9: 0.065 | AG9: =(I9+Y9)^0.026*0.66 -> 0.77606195 | AH9: =(J9+W9)*0.398*0.5 -> 0 | AI9: =(AA9)^0.335*0.66 -> 0 | AJ9: =(E9+Z9)*1.33 -> 0.61978 | AK9: =(F9+X9)*1.33 -> 0.11571 | AL9: =(G9+AB9)*1.06 -> 0 | AM9: =(U9+AC9)*2 -> 0 | AN9: =(V9+AD9)*1 -> 0 | AO9: =(H9+AE9)*1 -> 61 | AP9: =(K9+AF9)*1.1979 -> 0.0778635 | AQ9: =L9+M9+N9+O9+P9+Q9+R9+S9 -> 0 | AR9: =T9 -> 0 | AS9: =AG9*$AG$4+AH9*$AH$4+AI9*$AI$4+AJ9*$AJ$4+AK9*$AK$4+AL9*$AL$4+AM9*$AM$4+AN9*$AN$4+AO9*$AO$4+AP9*$AP$4+AQ9*$AQ$4+AR9*$AR$4 -> 154.10221
A10: 6 | B10: 黄金剧团 | C10: 杯 | D10: 20 | AG10: =(I10+Y10)^0.026*0.66 -> 0 | AH10: =(J10+W10)*0.398*0.5 -> 0 | AI10: =(AA10)^0.335*0.66 -> 0 | AJ10: =(E10+Z10)*1.33 -> 0 | AK10: =(F10+X10)*1.33 -> 0 | AL10: =(G10+AB10)*1.06 -> 0 | AM10: =(U10+AC10)*2 -> 0 | AN10: =(V10+AD10)*1 -> 0 | AO10: =(H10+AE10)*1 -> 0 | AP10: =(K10+AF10)*1.1979 -> 0 | AQ10: =L10+M10+N10+O10+P10+Q10+R10+S10 -> 0 | AR10: =T10 -> 0 | AS10: =AG10*$AG$4+AH10*$AH$4+AI10*$AI$4+AJ10*$AJ$4+AK10*$AK$4+AL10*$AL$4+AM10*$AM$4+AN10*$AN$4+AO10*$AO$4+AP10*$AP$4+AQ10*$AQ$4+AR10*$AR$4 -> 0
A11: 7 | B11: 黄金剧团 | C11: 冠 | D11: 20 | AG11: =(I11+Y11)^0.026*0.66 -> 0 | AH11: =(J11+W11)*0.398*0.5 -> 0 | AI11: =(AA11)^0.335*0.66 -> 0 | AJ11: =(E11+Z11)*1.33 -> 0 | AK11: =(F11+X11)*1.33 -> 0 | AL11: =(G11+AB11)*1.06 -> 0 | AM11: =(U11+AC11)*2 -> 0 | AN11: =(V11+AD11)*1 -> 0 | AO11: =(H11+AE11)*1 -> 0 | AP11: =(K11+AF11)*1.1979 -> 0 | AQ11: =L11+M11+N11+O11+P11+Q11+R11+S11 -> 0 | AR11: =T11 -> 0 | AS11: =AG11*$AG$4+AH11*$AH$4+AI11*$AI$4+AJ11*$AJ$4+AK11*$AK$4+AL11*$AL$4+AM11*$AM$4+AN11*$AN$4+AO11*$AO$4+AP11*$AP$4+AQ11*$AQ$4+AR11*$AR$4 -> 0
A12: 8 | B12: 黄金剧团 | C12: 冠 | D12: 20 | AG12: =(I12+Y12)^0.026*0.66 -> 0 | AH12: =(J12+W12)*0.398*0.5 -> 0 | AI12: =(AA12)^0.335*0.66 -> 0 | AJ12: =(E12+Z12)*1.33 -> 0 | AK12: =(F12+X12)*1.33 -> 0 | AL12: =(G12+AB12)*1.06 -> 0 | AM12: =(U12+AC12)*2 -> 0 | AN12: =(V12+AD12)*1 -> 0 | AO12: =(H12+AE12)*1 -> 0 | AP12: =(K12+AF12)*1.1979 -> 0 | AQ12: =L12+M12+N12+O12+P12+Q12+R12+S12 -> 0 | AR12: =T12 -> 0 | AS12: =AG12*$AG$4+AH12*$AH$4+AI12*$AI$4+AJ12*$AJ$4+AK12*$AK$4+AL12*$AL$4+AM12*$AM$4+AN12*$AN$4+AO12*$AO$4+AP12*$AP$4+AQ12*$AQ$4+AR12*$AR$4 -> 0
A13: 9 | AG13: =(I13+Y13)^0.026*0.66 -> 0 | AH13: =(J13+W13)*0.398*0.5 -> 0 | AI13: =(AA13)^0.335*0.66 -> 0 | AJ13: =(E13+Z13)*1.33 -> 0 | AK13: =(F13+X13)*1.33 -> 0 | AL13: =(G13+AB13)*1.06 -> 0 | AM13: =(U13+AC13)*2 -> 0 | AN13: =(V13+AD13)*1 -> 0 | AO13: =(H13+AE13)*1 -> 0 | AP13: =(K13+AF13)*1.1979 -> 0 | AQ13: =L13+M13+N13+O13+P13+Q13+R13+S13 -> 0 | AR13: =T13 -> 0 | AS13: =AG13*$AG$4+AH13*$AH$4+AI13*$AI$4+AJ13*$AJ$4+AK13*$AK$4+AL13*$AL$4+AM13*$AM$4+AN13*$AN$4+AO13*$AO$4+AP13*$AP$4+AQ13*$AQ$4+AR13*$AR$4 -> 0
A14: 10 | B14: 绝缘之旗印 | C14: 花 | D14: 0 | I14: 717 | W14: 18 | Z14: 0.041 | AE14: 23 | AF14: 0.065 | AG14: =(I14+Y14)^0.026*0.66 -> 0.78304629 | AH14: =(J14+W14)*0.398*0.5 -> 3.582 | AI14: =(AA14)^0.335*0.66 -> 0 | AJ14: =(E14+Z14)*1.33 -> 0.05453 | AK14: =(F14+X14)*1.33 -> 0 | AL14: =(G14+AB14)*1.06 -> 0 | AM14: =(U14+AC14)*2 -> 0 | AN14: =(V14+AD14)*1 -> 0 | AO14: =(H14+AE14)*1 -> 23 | AP14: =(K14+AF14)*1.1979 -> 0.0778635 | AQ14: =L14+M14+N14+O14+P14+Q14+R14+S14 -> 0 | AR14: =T14 -> 0 | AS14: =AG14*$AG$4+AH14*$AH$4+AI14*$AI$4+AJ14*$AJ$4+AK14*$AK$4+AL14*$AL$4+AM14*$AM$4+AN14*$AN$4+AO14*$AO$4+AP14*$AP$4+AQ14*$AQ$4+AR14*$AR$4 -> 358.24739
A15: 11 | B15: 绝缘之旗印 | C15: 羽 | D15: 8 | J15: 152 | X15: 0.053 | Z15: 0.041 | AA15: 39 | AF15: 0.052 | AG15: =(I15+Y15)^0.026*0.66 -> 0 | AH15: =(J15+W15)*0.398*0.5 -> 30.248 | AI15: =(AA15)^0.335*0.66 -> 2.2519077 | AJ15: =(E15+Z15)*1.33 -> 0.05453 | AK15: =(F15+X15)*1.33 -> 0.07049 | AL15: =(G15+AB15)*1.06 -> 0 | AM15: =(U15+AC15)*2 -> 0 | AN15: =(V15+AD15)*1 -> 0 | AO15: =(H15+AE15)*1 -> 0 | AP15: =(K15+AF15)*1.1979 -> 0.0622908 | AQ15: =L15+M15+N15+O15+P15+Q15+R15+S15 -> 0 | AR15: =T15 -> 0 | AS15: =AG15*$AG$4+AH15*$AH$4+AI15*$AI$4+AJ15*$AJ$4+AK15*$AK$4+AL15*$AL$4+AM15*$AM$4+AN15*$AN$4+AO15*$AO$4+AP15*$AP$4+AQ15*$AQ$4+AR15*$AR$4 -> 2284.0116
A16: 12 | B16: 绝缘之旗印 | C16: 沙 | D16: 0 | G16: 8.7 | Y16: 209 | Z16: 0.041 | AF16: 0.045 | AG16: =(I16+Y16)^0.026*0.66 -> 0.75834659 | AH16: =(J16+W16)*0.398*0.5 -> 0 | AI16: =(AA16)^0.335*0.66 -> 0 | AJ16: =(E16+Z16)*1.33 -> 0.05453 | AK16: =(F16+X16)*1.33 -> 0 | AL16: =(G16+AB16)*1.06 -> 9.222 | AM16: =(U16+AC16)*2 -> 0 | AN16: =(V16+AD16)*1 -> 0 | AO16: =(H16+AE16)*1 -> 0 | AP16: =(K16+AF16)*1.1979 -> 0.0539055 | AQ16: =L16+M16+N16+O16+P16+Q16+R16+S16 -> 0 | AR16: =T16 -> 0 | AS16: =AG16*$AG$4+AH16*$AH$4+AI16*$AI$4+AJ16*$AJ$4+AK16*$AK$4+AL16*$AL$4+AM16*$AM$4+AN16*$AN$4+AO16*$AO$4+AP16*$AP$4+AQ16*$AQ$4+AR16*$AR$4 -> 85.330572
A17: 13 | B17: 绝缘之旗印 | C17: 杯 | D17: 0 | P17: 0.07 | X17: 0.047 | AC17: 0.031 | AD17: 0.062 | AE17: 19 | AG17: =(I17+Y17)^0.026*0.66 -> 0 | AH17: =(J17+W17)*0.398*0.5 -> 0 | AI17: =(AA17)^0.335*0.66 -> 0 | AJ17: =(E17+Z17)*1.33 -> 0 | AK17: =(F17+X17)*1.33 -> 0.06251 | AL17: =(G17+AB17)*1.06 -> 0 | AM17: =(U17+AC17)*2 -> 0.062 | AN17: =(V17+AD17)*1 -> 0.062 | AO17: =(H17+AE17)*1 -> 19 | AP17: =(K17+AF17)*1.1979 -> 0 | AQ17: =L17+M17+N17+O17+P17+Q17+R17+S17 -> 0.07 | AR17: =T17 -> 0 | AS17: =AG17*$AG$4+AH17*$AH$4+AI17*$AI$4+AJ17*$AJ$4+AK17*$AK$4+AL17*$AL$4+AM17*$AM$4+AN17*$AN$4+AO17*$AO$4+AP17*$AP$4+AQ17*$AQ$4+AR17*$AR$4 -> 24.08825
A18: 14 | B18: 绝缘之旗印 | C18: 冠 | D18: 0 | V18: 0.093 | W18: 18 | Z18: 0.058 | AA18: 23 | AF18: 0.045 | AG18: =(I18+Y18)^0.026*0.66 -> 0 | AH18: =(J18+W18)*0.398*0.5 -> 3.582 | AI18: =(AA18)^0.335*0.66 -> 1.8867865 | AJ18: =(E18+Z18)*1.33 -> 0.07714 | AK18: =(F18+X18)*1.33 -> 0 | AL18: =(G18+AB18)*1.06 -> 0 | AM18: =(U18+AC18)*2 -> 0 | AN18: =(V18+AD18)*1 -> 0.093 | AO18: =(H18+AE18)*1 -> 0 | AP18: =(K18+AF18)*1.1979 -> 0.0539055 | AQ18: =L18+M18+N18+O18+P18+Q18+R18+S18 -> 0 | AR18: =T18 -> 0 | AS18: =AG18*$AG$4+AH18*$AH$4+AI18*$AI$4+AJ18*$AJ$4+AK18*$AK$4+AL18*$AL$4+AM18*$AM$4+AN18*$AN$4+AO18*$AO$4+AP18*$AP$4+AQ18*$AQ$4+AR18*$AR$4 -> 289.70691
A19: 15 | AG19: =(I19+Y19)^0.026*0.66 -> 0 | AH19: =(J19+W19)*0.398*0.5 -> 0 | AI19: =(AA19)^0.335*0.66 -> 0 | AJ19: =(E19+Z19)*1.33 -> 0 | AK19: =(F19+X19)*1.33 -> 0 | AL19: =(G19+AB19)*1.06 -> 0 | AM19: =(U19+AC19)*2 -> 0 | AN19: =(V19+AD19)*1 -> 0 | AO19: =(H19+AE19)*1 -> 0 | AP19: =(K19+AF19)*1.1979 -> 0 | AQ19: =L19+M19+N19+O19+P19+Q19+R19+S19 -> 0 | AR19: =T19 -> 0 | AS19: =AG19*$AG$4+AH19*$AH$4+AI19*$AI$4+AJ19*$AJ$4+AK19*$AK$4+AL19*$AL$4+AM19*$AM$4+AN19*$AN$4+AO19*$AO$4+AP19*$AP$4+AQ19*$AQ$4+AR19*$AR$4 -> 0
A20: 16 | AG20: =(I20+Y20)^0.026*0.66 -> 0 | AH20: =(J20+W20)*0.398*0.5 -> 0 | AI20: =(AA20)^0.335*0.66 -> 0 | AJ20: =(E20+Z20)*1.33 -> 0 | AK20: =(F20+X20)*1.33 -> 0 | AL20: =(G20+AB20)*1.06 -> 0 | AM20: =(U20+AC20)*2 -> 0 | AN20: =(V20+AD20)*1 -> 0 | AO20: =(H20+AE20)*1 -> 0 | AP20: =(K20+AF20)*1.1979 -> 0 | AQ20: =L20+M20+N20+O20+P20+Q20+R20+S20 -> 0 | AR20: =T20 -> 0 | AS20: =AG20*$AG$4+AH20*$AH$4+AI20*$AI$4+AJ20*$AJ$4+AK20*$AK$4+AL20*$AL$4+AM20*$AM$4+AN20*$AN$4+AO20*$AO$4+AP20*$AP$4+AQ20*$AQ$4+AR20*$AR$4 -> 0
A21: 17 | AG21: =(I21+Y21)^0.026*0.66 -> 0 | AH21: =(J21+W21)*0.398*0.5 -> 0 | AI21: =(AA21)^0.335*0.66 -> 0 | AJ21: =(E21+Z21)*1.33 -> 0 | AK21: =(F21+X21)*1.33 -> 0 | AL21: =(G21+AB21)*1.06 -> 0 | AM21: =(U21+AC21)*2 -> 0 | AN21: =(V21+AD21)*1 -> 0 | AO21: =(H21+AE21)*1 -> 0 | AP21: =(K21+AF21)*1.1979 -> 0 | AQ21: =L21+M21+N21+O21+P21+Q21+R21+S21 -> 0 | AR21: =T21 -> 0 | AS21: =AG21*$AG$4+AH21*$AH$4+AI21*$AI$4+AJ21*$AJ$4+AK21*$AK$4+AL21*$AL$4+AM21*$AM$4+AN21*$AN$4+AO21*$AO$4+AP21*$AP$4+AQ21*$AQ$4+AR21*$AR$4 -> 0
A22: 18 | AG22: =(I22+Y22)^0.026*0.66 -> 0 | AH22: =(J22+W22)*0.398*0.5 -> 0 | AI22: =(AA22)^0.335*0.66 -> 0 | AJ22: =(E22+Z22)*1.33 -> 0 | AK22: =(F22+X22)*1.33 -> 0 | AL22: =(G22+AB22)*1.06 -> 0 | AM22: =(U22+AC22)*2 -> 0 | AN22: =(V22+AD22)*1 -> 0 | AO22: =(H22+AE22)*1 -> 0 | AP22: =(K22+AF22)*1.1979 -> 0 | AQ22: =L22+M22+N22+O22+P22+Q22+R22+S22 -> 0 | AR22: =T22 -> 0 | AS22: =AG22*$AG$4+AH22*$AH$4+AI22*$AI$4+AJ22*$AJ$4+AK22*$AK$4+AL22*$AL$4+AM22*$AM$4+AN22*$AN$4+AO22*$AO$4+AP22*$AP$4+AQ22*$AQ$4+AR22*$AR$4 -> 0
A23: 19
A24: 20
A25: 21
A26: 22
A27: 23
A28: 24
A29: 25
A30: 26
A31: 27
A32: 28
A33: 29
A34: 30
... A54: 50

Sheet 秘境汇总
C1: 周一 | D1: 周二 | E1: 周三 | F1: 周四 | G1: 周五 | H1: 周六 | I1: 周日 | K1: 角色培养材料 | Q1: 1 | R1: 2 | S1: 3 | T1: 4 | U1: 5 | V1: 6 | W1: 7 | Y1: 自由 抗争 诗文 | Z1: 1 | AC1: 1 | AF1: 1
A2: 深潮的余响 | B2: 武器突破素材 | C2: 悠古弦音的断章 | D2: 纯圣露滴的真粹 | E2: 无垢之海的银杯 | F2: 悠古弦音的断章 | G2: 纯圣露滴的真粹 | H2: 无垢之海的银杯 | I2: 悠古弦音的断章 | P2: 秩序 | S2: 1 | V2: 1 | W2: 1 | Y2: 抗争 | AA2: 1 | AD2: 1 | AF2: 1
A3: 有顶塔 | B3: 武器突破素材 | C3: 谧林涓露的银符 | D3: 绿洲花园的真谛 | E3: 烈日威权的余光 | F3: 谧林涓露的银符 | G3: 绿洲花园的真谛 | H3: 烈日威权的余光 | I3: 谧林涓露的银符 | P3: 巧思 | R3: 1 | U3: 1 | W3: 1 | Y3: 诗文 | AB3: 1 | AE3: 1 | AF3: 1
A4: 砂流之庭 | B4: 武器突破素材 | C4: 远海夷地的玉枝 | D4: 鸣神御灵的勇武 | E4: 今昔剧画之一角 | F4: 远海夷地的玉枝 | G4: 鸣神御灵的勇武 | H4: 今昔剧画之一角 | I4: 远海夷地的玉枝 | P4: 诗文 | S4: 1 | V4: 1 | W4: 1
A5: 震雷连山密宫 | B5: 武器突破素材 | C5: 孤云寒林的神体 | D5: 雾海云间的转还 | E5: 漆黑陨铁的一片 | F5: 孤云寒林的神体 | G5: 雾海云间的转还 | H5: 漆黑陨铁的一片 | I5: 孤云寒林的神体 | P5: 浮世 | Q5: 1 | T5: 1 | W5: 1 | Y5: 公平 正义 秩序 | Z5: 1 | AC5: 1 | AF5: 1
A6: 塞西莉亚苗圃 | B6: 武器突破素材 | C6: 高塔孤王的碎梦 | D6: 凛风奔狼的始戴 | E6: 狮牙斗士的铁链 | F6: 高塔孤王的碎梦 | G6: 凛风奔狼的始戴 | H6: 狮牙斗士的铁链 | I6: 高塔孤王的碎梦 | P6: 公平 | Q6: 1 | T6: 1 | W6: 1 | Y6: 正义 | AA6: 1 | AD6: 1 | AF6: 1
B7: 悠古弦音的断章 | C7: 1 | F7: 1 | I7: 1 | K7: 零落丘墟 | L7: 残火灯烛 | M7: 否定裁断 | N7: 丝织之羽 | P7: 笃行 | S7: 1 | V7: 1 | W7: 1 | Y7: 秩序 | AB7: 1 | AE7: 1 | AF7: 1
B8: 谧林涓露的银符 | C8: 1 | F8: 1 | I8: 1 | K8: 梦想乐土之殁 | P8: 繁荣 | Q8: 1 | T8: 1 | W8: 1
B9: 远海夷地的玉枝 | C9: 1 | F9: 1 | I9: 1 | K9: 异界余影 | P9: 风雅 | R9: 1 | U9: 1 | W9: 1 | Y9: 净言 巧思 笃行 | Z9: 1 | AC9: 1 | AF9: 1
B10: 孤云寒林的神体 | C10: 1 | F10: 1 | I10: 1 | K10: 鸣神岛·天守 | P10: 正义 | R10: 1 | U10: 1 | W10: 1 | Y10: 巧思 | AA10: 1 | AD10: 1 | AF10: 1
B11: 高塔孤王的碎梦 | C11: 1 | F11: 1 | I11: 1 | K11: 肇始之乡 | P11: 自由 | Q11: 1 | T11: 1 | W11: 1 | Y11: 笃行 | AB11: 1 | AE11: 1 | AF11: 1
B12: 纯圣露滴的真粹 | D12: 1 | G12: 1 | I12: 1 | K12: 「伏龙树」之底 | P12: 勤劳 | R12: 1 | U12: 1 | W12: 1
B13: 绿洲花园的真谛 | D13: 1 | G13: 1 | I13: 1 | K13: 净琉璃工坊 | P13: 天光 | S13: 1 | V13: 1 | W13: 1 | Y13: 浮世 风雅 天光 | Z13: 1 | AC13: 1 | AF13: 1
B14: 鸣神御灵的勇武 | D14: 1 | G14: 1 | I14: 1 | K14: 进入「黄金屋」 | P14: 净言 | Q14: 1 | T14: 1 | W14: 1 | Y14: 风雅 | AA14: 1 | AD14: 1 | AF14: 1
B15: 雾海云间的转还 | D15: 1 | G15: 1 | I15: 1 | K15: 深入风龙废墟 | P15: 抗争 | R15: 1 | U15: 1 | W15: 1 | Y15: 天光 | AB15: 1 | AE15: 1 | AF15: 1
B16: 凛风奔狼的始戴 | D16: 1 | G16: 1 | I16: 1 | P16: 黄金 | S16: 1 | V16: 1 | W16: 1
B17: 无垢之海的银杯 | E17: 1 | H17: 1 | I17: 1 | P17: 智识之冕 | Y17: 自由 抗争 诗文 | Z17: 1 | AC17: 1 | AF17: 1
B18: 烈日威权的余光 | E18: 1 | H18: 1 | I18: 1 | Y18: 抗争 | AA18: 1 | AD18: 1 | AF18: 1
B19: 今昔剧画之一角 | E19: 1 | H19: 1 | I19: 1 | Y19: 诗文 | AB19: 1 | AE19: 1 | AF19: 1
B20: 漆黑陨铁的一片 | E20: 1 | H20: 1 | I20: 1
B21: 狮牙斗士的铁链 | E21: 1 | H21: 1 | I21: 1

Sheet --
C1: 名字 | D1: 编号 | E1: 名字 | F1: 编号 | H1: HP | I1: ATK | J1: DEF | K1: CR | L1: CD | M1: EM | N1: ER
C2: Klee | D2: 48 | E2: Klee | F2: 1 | G2: 可莉 | H2: 0 | I2: 75 | J2: 0 | K2: 100 | L2: 100 | M2: 75 | N2: 0 | S2: 名字 | T2: 编号 | U2: 名字 | V2: 编号 | AD2: Arifacts Rating Algorithm | AF2: ARIMCES评分算法 | AH2: 角色统计效益权重
C3: Venti | D3: 35 | E3: Venti | F3: 2 | G3: 温迪 | H3: 0 | I3: 75 | J3: 0 | K3: 100 | L3: 100 | M3: 75 | N3: 55 | S3: Albedo | T3: 38 | U3: Albedo | V3: 26 | W3: 阿贝多 | AD3: Substats | AE3: Fommula | AF3: 子统计数据 | AI3: HP | AJ3: ATK | AK3: DEF | AL3: CRIT Rate | AM3: CRIT DMG | AN3: EM | AO3: ER
C4: Keqing | D4: 51 | E4: Keqing | F4: 3 | G4: 刻晴 | H4: 0 | I4: 75 | J4: 0 | K4: 100 | L4: 100 | M4: 75 | N4: 0 | S4: Alhaitham | T4: 5 | U4: Alhaitham | V4: 62 | W4: 艾尔海森 | AD4: CRIT Rate | AE4: Rating=CRiT Rate*2*Benefit Weight | AF4: 暴击率 | AI4: 生命值 | AJ4: 攻击力 | AK4: 防御力 | AL4: 暴击率 | AM4: 暴击伤害 | AN4: 元素精通 | AO4: 元素充能
C5: Mona | D5: 37 | E5: Mona | F5: 4 | G5: 莫娜 | H5: 0 | I5: 75 | J5: 0 | K5: 100 | L5: 100 | M5: 75 | N5: 75 | S5: Aloy | T5: 67 | U5: Aloy | V5: 37 | W5: 埃洛伊 | AD5: CRIT DMG | AE5: Rating=CRIT DMG*1*Beneft Weight | AF5: 暴击伤害 | AH5: Mika
C6: Qiqi | D6: 61 | E6: Qiqi | F6: 5 | G6: 七七 | H6: 0 | I6: 100 | J6: 0 | K6: 100 | L6: 100 | M6: 0 | N6: 55 | S6: Ambor | T6: 65 | U6: Amber | V6: 21 | W6: 安柏 | AD6: EM | AE6: Rating=EM*0.33 Benefit Weight | AF6: 元素精通 | AH6: Dehya
C7: Diluc | D7: 53 | E7: Diluc | F7: 6 | G7: 迪卢克 | H7: 0 | I7: 75 | J7: 0 | K7: 100 | L7: 100 | M7: 75 | N7: 0 | S7: Ayaka | T7: 31 | U7: Kamizato Ayaka | V7: 34 | W7: 神里绫华 | AD7: ER | AE7: Rating=ER*1.1979"Benefit Weight | AF7: 元素充能 | AH7: Alhaitham
C8: Jean | D8: 45 | E8: Jean | F8: 7 | G8: 琴 | H8: 0 | I8: 75 | J8: 0 | K8: 100 | L8: 100 | M8: 75 | N8: 55 | S8: Ayato | T8: 20 | U8: Kamizato Ayato | V8: 47 | W8: 神里绫人 | AD8: ATK% | AE8: Rating=ATK%*1.33*Benefit Weight | AF8: 攻击力百分比 | AH8: Yaoyao
C9: Sucrose | D9: 69 | E9: Sucrose | F9: 8 | G9: 砂糖 | H9: 0 | I9: 75 | J9: 0 | K9: 100 | L9: 100 | M9: 100 | N9: 55 | S9: Barbara | T9: 54 | U9: Barbara | V9: 18 | W9: 芭芭拉 | AD9: HP% | AE9: Rating=HP%*1.33*Beneft Weight | AF9: 生命值百分比 | AH9: Wianderer
C10: Chongyun | D10: 60 | E10: Chongyun | F10: 9 | G10: 重云 | H10: 0 | I10: 75 | J10: 0 | K10: 100 | L10: 100 | M10: 75 | N10: 55 | S10: Beidou | T10: 50 | U10: Beidou | V10: 15 | W10: 北斗 | AD10: DEF% | AE10: Rating=DEF%*1.06*Beneft Weight | AF10: 防御力百分比 | AH10: FaruZan
C11: Noel | D11: 55 | E11: Noelle | F11: 10 | G11: 诺艾尔 | H11: 0 | I11: 50 | J11: 90 | K11: 100 | L11: 100 | M11: 0 | N11: 70 | S11: Bennett | T11: 26 | U11: Bennett | V11: 11 | W11: 班尼特 | AD11: ATK | AE11: Rating=ATK*0.398*0 5*Benefit Weight | AF11: 攻击力 | AH11: Nahida
C12: Bennett | D12: 26 | E12: Bennett | F12: 11 | G12: 班尼特 | H12: 100 | I12: 50 | J12: 0 | K12: 50 | L12: 50 | M12: 0 | N12: 55 | S12: Candace | T12: 13 | U12: Candace | V12: 54 | W12: 坎蒂丝 | AD12: HP | AE12: Rating=HP^0.026*0 66*Beneft Weight | AF12: 生命值 | AH12: Layia
C13: Fischl | D13: 46 | E13: Fischl | F13: 12 | G13: 菲谢尔 | H13: 0 | I13: 75 | J13: 0 | K13: 100 | L13: 100 | M13: 75 | N13: 0 | S13: Chongyun | T13: 60 | U13: Chongyun | V13: 9 | W13: 重云 | AD13: DEF | AE13: Rating=DEF^0 .335*0 66*Benefit Weight | AF13: 防御力 | AH13: Nilou
C14: Ningguang | D14: 49 | E14: Ningguang | F14: 13 | G14: 凝光 | H14: 0 | I14: 75 | J14: 0 | K14: 100 | L14: 100 | M14: 0 | N14: 0 | S14: Collei | T14: 16 | U14: Collei | V14: 51 | W14: 柯莱 | AH14: Cyno
C15: Xingqiu | D15: 29 | E15: Xingqiu | F15: 14 | G15: 行秋 | H15: 0 | I15: 75 | J15: 0 | K15: 100 | L15: 100 | M15: 0 | N15: 55 | S15: Cyno | T15: 12 | U15: Cyno | V15: 55 | W15: 赛诺 | AH15: Candace
C16: Beidou | D16: 50 | E16: Beidou | F16: 15 | G16: 北斗 | H16: 0 | I16: 75 | J16: 0 | K16: 100 | L16: 100 | M16: 75 | N16: 55 | S16: Dehya | T16: 4 | U16: Dehya | V16: 63 | W16: 迪希雅 | AH16: Dori
C17: Xiangling | D17: 32 | E17: Xiangling | F17: 16 | G17: 香菱 | H17: 0 | I17: 75 | J17: 0 | K17: 100 | L17: 100 | M17: 75 | N17: 55 | S17: Diluc | T17: 53 | U17: Diluc | V17: 6 | W17: 迪卢克 | AH17: Tighnari
C18: Razor | D18: 70 | E18: Razor | F18: 17 | G18: 雷泽 | H18: 0 | I18: 75 | J18: 0 | K18: 100 | L18: 100 | M18: 0 | N18: 0 | S18: Diona | T18: 39 | U18: Diona | V18: 23 | W18: 迪奥娜 | AH18: Collei
C19: Barbara | D19: 54 | E19: Barbara | F19: 18 | G19: 芭芭拉 | H19: 100 | I19: 50 | J19: 0 | K19: 50 | L19: 50 | M19: 0 | N19: 55 | S19: Dori | T19: 14 | U19: Dori | V19: 53 | W19: 多莉 | AH19: Heizou
C20: Lisa | D20: 66 | E20: Lisa | F20: 19 | G20: 丽莎 | H20: 0 | I20: 75 | J20: 0 | K20: 100 | L20: 100 | M20: 75 | N20: 0 | S20: Eula | T20: 40 | U20: Eula | V20: 32 | W20: 优菈 | AH20: Shinobu
C21: Kaeya | D21: 62 | E21: Kaeya | F21: 20 | G21: 凯亚 | H21: 0 | I21: 75 | J21: 0 | K21: 100 | L21: 100 | M21: 0 | N21: 0 | S21: Faruzan | T21: 8 | U21: Faruzan | V21: 59 | W21: 珐露珊 | AH21: Yelan
C22: Ambor | D22: 65 | E22: Amber | F22: 21 | G22: 安柏 | H22: 0 | I22: 75 | J22: 0 | K22: 100 | L22: 100 | M22: 75 | N22: 0 | S22: Feiyan | T22: 63 | U22: Yanfei | V22: 31 | W22: 烟绯 | AH22: Ayato
C23: Tartaglia | D23: 41 | E23: Tartaglia | F23: 22 | G23: 达达利亚 | H23: 0 | I23: 75 | J23: 0 | K23: 100 | L23: 100 | M23: 75 | N23: 0 | S23: Fischl | T23: 46 | U23: Fischl | V23: 12 | W23: 菲谢尔 | AH23: Yae
C24: Diona | D24: 39 | E24: Diona | F24: 23 | G24: 迪奥娜 | H24: 100 | I24: 50 | J24: 0 | K24: 50 | L24: 50 | M24: 0 | N24: 90 | S24: Ganyu | T24: 34 | U24: Ganyu | V24: 27 | W24: 甘雨 | AH24: Shenhe
C25: Zhongli | D25: 30 | E25: Zhongli | F25: 24 | G25: 钟离 | H25: 80 | I25: 75 | J25: 0 | K25: 100 | L25: 100 | M25: 0 | N25: 55 | S25: Gorou | T25: 25 | U25: Gorou | V25: 42 | W25: 五郎 | AH25: Yunjin
... C37: Yoimiya | D37: 43 | E37: Yoimiya | F37: 36 | G37: 宵宫 | H37: 0 | I37: 75 | J37: 0 | K37: 100 | L37: 100 | M37: 75 | N37: 0 | S37: Mika | T37: 3 | U37: Mika | V37: 64 | W37: 米卡 | AH37: Ventl
C38: Aloy | D38: 67 | E38: Aloy | F38: 37 | G38: 埃洛伊 | H38: 0 | I38: 75 | J38: 0 | K38: 100 | L38: 100 | M38: 0 | N38: 0 | S38: Mona | T38: 37 | U38: Mona | V38: 4 | W38: 莫娜
C39: Sara | D39: 44 | E39: Kujo Sara | F39: 38 | G39: 九条裟罗 | H39: 0 | I39: 75 | J39: 0 | K39: 100 | L39: 100 | M39: 0 | N39: 55 | S39: Nahida | T39: 9 | U39: Nahida | V39: 57 | W39: 纳西妲
C40: Shougun | D40: 28 | E40: Raiden Shogun | F40: 39 | G40: 雷电将军 | H40: 0 | I40: 75 | J40: 0 | K40: 100 | L40: 100 | M40: 0 | N40: 75 | S40: Nilou | T40: 11 | U40: Nilou | V40: 56 | W40: 妮露 | Y40: Kaveh | Z40: 65 | AA40: 卡维
C41: Kokomi | D41: 36 | E41: Sangonomiya Kokomi | F41: 40 | G41: 珊瑚宫心海 | H41: 100 | I41: 50 | J41: 0 | K41: 0 | L41: 0 | M41: 75 | N41: 55 | S41: Ningguang | T41: 49 | U41: Ningguang | V41: 13 | W41: 凝光 | Y41: Baizhu | Z41: 66 | AA41: 白术
C42: Tohma | D42: 52 | E42: Thoma | F42: 41 | G42: 托马 | H42: 100 | I42: 50 | J42: 0 | K42: 50 | L42: 50 | M42: 0 | N42: 90 | S42: Noel | T42: 55 | U42: Noelle | V42: 10 | W42: 诺艾尔 | Y42: Kirara | Z42: 67 | AA42: 绮良良
C43: Gorou | D43: 25 | E43: Gorou | F43: 42 | G43: 五郎 | H43: 0 | I43: 50 | J43: 100 | K43: 50 | L43: 50 | M43: 0 | N43: 90 | S43: Qiqi | T43: 61 | U43: Qiqi | V43: 5 | W43: 七七 | Y43: Lynette | Z43: 68 | AA43: 琳妮特
C44: ltto | D44: 24 | E44: Arataki Itto | F44: 43 | G44: 荒泷一斗 | H44: 0 | I44: 50 | J44: 100 | K44: 100 | L44: 100 | M44: 0 | N44: 30 | S44: Razor | T44: 70 | U44: Razor | V44: 17 | W44: 雷泽 | Y44: Lyney | Z44: 69 | AA44: 林尼
C45: Yunjin | D45: 23 | E45: Yun Jin | F45: 44 | G45: 云堇 | H45: 0 | I45: 0 | J45: 100 | K45: 50 | L45: 50 | M45: 0 | N45: 90 | S45: Rosaria | T45: 47 | U45: Rosaria | V45: 30 | W45: 罗莎莉亚 | Y45: Freminet | Z45: 70 | AA45: 菲米尼
C46: Shenhe | D46: 22 | E46: Shenhe | F46: 45 | G46: 申鹤 | H46: 0 | I46: 100 | J46: 0 | K46: 100 | L46: 100 | M46: 0 | N46: 55 | S46: Sara | T46: 44 | U46: Kujo Sara | V46: 38 | W46: 九条裟罗 | Y46: Neuvillette | Z46: 71 | AA46: 那维莱特
C47: Yae | D47: 21 | E47: Yae Miko | F47: 46 | G47: 八重神子 | H47: 0 | I47: 75 | J47: 0 | K47: 100 | L47: 100 | M47: 75 | N47: 0 | S47: Sayu | T47: 64 | U47: Sayu | V47: 35 | W47: 早柚 | Y47: Wriothesley | Z47: 72 | AA47: 莱欧斯利
C48: Ayato | D48: 20 | E48: Kamizato Ayato | F48: 47 | G48: 神里绫人 | H48: 50 | I48: 75 | J48: 0 | K48: 100 | L48: 100 | M48: 0 | N48: 0 | S48: Shenhe | T48: 22 | U48: Shenhe | V48: 45 | W48: 申鹤 | Y48: Charlotte | Z48: 73 | AA48: 夏洛蒂
C49: Yelan | D49: 19 | E49: Yelan | F49: 48 | G49: 夜兰 | H49: 80 | I49: 0 | J49: 0 | K49: 100 | L49: 100 | M49: 0 | N49: 55 | S49: Shinobu | T49: 18 | U49: Kuki shinobu | V49: 49 | W49: 久岐忍 | Y49: Furina | Z49: 74 | AA49: 芙宁娜
C50: Shinobu | D50: 18 | E50: Kuki shinobu | F50: 49 | G50: 久岐忍 | H50: 100 | I50: 75 | J50: 0 | K50: 50 | L50: 50 | M50: 100 | N50: 55 | S50: Shougun | T50: 28 | U50: Raiden Shogun | V50: 39 | W50: 雷电将军 | Y50: Navia | Z50: 75 | AA50: 娜维娅
C51: Heizou | D51: 17 | E51: Shikanoin Heizou | F51: 50 | G51: 鹿野院平藏 | H51: 0 | I51: 75 | J51: 0 | K51: 100 | L51: 100 | M51: 75 | N51: 0 | S51: Sucrose | T51: 69 | U51: Sucrose | V51: 8 | W51: 砂糖 | Y51: Chevreuse | Z51: 76 | AA51: 夏沃蕾
...
